Workbook

Sheet Portada
B3: PADEL PALMIRA CLUB DEPORTIVO
B5: Estados Financieros para Inversionistas
B6: Estado de Resultados · Balance General · Estado de Flujo de Efectivo · Proyección integrada a 3 años · Valuación
B8: Cifras en pesos mexicanos (MXN) · Periodo histórico: noviembre 2024 – mayo 2026 (19 meses) · Estados no auditados, preparados con base en los registros internos del club
B10: Contenido
B11: 1. Supuestos — parámetros del modelo (celdas en azul / fondo amarillo = editables)
B12: 2. Estado de Resultados — histórico por periodo, últimos 12 meses (TTM) y proyección a 3 años
B13: 3. Balance General — 30-abr-2026 (último corte bancario), 31-may-2026 (estimado) y proyección
B14: 4. Estado de Flujo de Efectivo — desde la apertura, con conciliación contra saldos bancarios
B15: 5. Valuación — terreno + negocio, múltiplo implícito y retorno ilustrativo para el comprador
B16: 6. Notas a los Estados Financieros
B17: 7. Base Mensual — registros mensuales que alimentan todos los estados
... B32: padelpalmira@gmail.com · Único canal de contacto para esta oportunidad

Sheet Supuestos
B2: Supuestos del Modelo
B3: Celdas con fondo amarillo = supuestos editables. Todas las hojas se recalculan al modificarlos.
B5: Supuesto | C5: Valor | D5: Fuente / comentario
B6: ACTIVO FIJO Y DEPRECIACIÓN
B7: Inversión inicial del proyecto (instalaciones, canchas, techumbre, equipo) | C7: 9128124 | D7: Dato del propietario ("Inversión Inicial Proyecto"). Se asume que NO incluye el terreno (propiedad de Promotora Goya). Desglose por componente pendiente.
B8: Tasa de depreciación anual ponderada | C8: 0.1 | D8: Supuesto conservador: tasa fiscal de mobiliario y equipo (10%). Construcciones deprecian al 5% (LISR art. 34) — con el desglose real la depreciación sería menor. Confirmar con el contador.
B9: Depreciación mensual resultante | C9: =Supuestos!C7*Supuestos!C8/12 -> 76067.7 | D9: Fórmula. Se deprecia desde noviembre 2024 (primer mes con registros de operación).
B10: IMPUESTOS
B11: Tasa de ISR (personas morales, régimen general) | C11: 0.3 | D11: Pro forma. Los registros del club no separan pagos de ISR/IVA; los estados históricos muestran el ISR que causaría la utilidad bajo régimen general. PTU no modelada.
B12: PROYECCIÓN (AÑOS 1–3: JUN-26 A MAY-29)
B13: Crecimiento anual de ingresos | C13: 0.115 | D13: Crecimiento de horas de cancha ocupadas año contra año (Playtomic, ene–may 2026 vs. ene–may 2025). Mismo supuesto que Reporte_Financiero.xlsx, hoja Proyecciones.
B14: Capex de mantenimiento (% de ingresos) | C14: 0.03 | D14: Reserva para reemplazos mayores (pasto sintético, vidrios, iluminación). Históricamente las reparaciones se registraron como gasto; este capex es adicional y conservador.
B15: Distribución de utilidades a socios (% de utilidad neta) | C15: 0 | D15: Decisión del comprador. Con 0% el efectivo se acumula en balance.
B16: Variación anual de capital de trabajo | C16: 0 | D16: Negocio de cobro inmediato (reservas y consumo pagados al momento): sin cuentas por cobrar relevantes. Se asume cero.
B17: BALANCE — DATOS PENDIENTES DE CONFIRMAR
B18: Inventario (bebidas, botana, pelotas, grips) al corte | C18: 0 | D18: PENDIENTE: capturar conteo físico valuado a costo.
B19: Proveedores y acreedores por pagar al corte | C19: 0 | D19: PENDIENTE: confirmar. Los registros no muestran cuentas por pagar.
B20: Impuestos por pagar al corte | C20: 0 | D20: PENDIENTE: confirmar con el contador situación de ISR/IVA de El Arroyo Investments.
B21: Deuda financiera | C21: 0 | D21: Según el propietario, el proyecto se financió con capital propio y el terreno está libre de gravámenes (sujeto a certificado de libertad de gravamen).
B22: Retiros de socios en mayo 2026 | C22: 0 | D22: PENDIENTE: la bitácora termina en marzo 2026. Afecta solo el balance estimado al 31-may-26.
B23: EFECTIVO — ÚLTIMO CORTE DE SALDOS (ABRIL 2026)
B24: Clip (terminal) | C24: 111744 | D24: Saldo reportado por el propietario (hoja de conciliación). Fecha exacta del corte por confirmar.
B25: BBVA | C25: 13054 | D25: Saldo reportado por el propietario (hoja de conciliación). Fecha exacta del corte por confirmar.
B26: Nu | C26: 113000 | D26: Saldo reportado por el propietario (hoja de conciliación). Fecha exacta del corte por confirmar.
B27: Ualá | C27: 103000 | D27: Saldo reportado por el propietario (hoja de conciliación). Fecha exacta del corte por confirmar.
B28: Didi | C28: 26700 | D28: Saldo reportado por el propietario (hoja de conciliación). Fecha exacta del corte por confirmar.
B29: Efectivo en caja | C29: 100000 | D29: Saldo reportado por el propietario (hoja de conciliación). Fecha exacta del corte por confirmar.
B30: Total efectivo al corte | C30: =SUM(C24:C29) -> 467498
B32: VALUACIÓN
B33: Superficie del terreno (m²) | C33: 3762 | D33: Escritura / Estudio de Valuación Inmobiliaria.
B34: Valor de tierra — conservador ($/m²) | C34: 7000 | D34: Estudio de Valuación Inmobiliaria (comparables de mercado). No es avalúo profesional.
B35: Valor de tierra — base ($/m²) | C35: 8000 | D35: Ídem.
B36: Valor de tierra — optimista ($/m²) | C36: 9500 | D36: Ídem.
B37: Múltiplo EV/EBITDA negocio — conservador | C37: 5 | D37: Rango de referencia para negocios deportivos/recreativos pequeños en México.
B38: Múltiplo EV/EBITDA negocio — base | C38: 6.5 | D38: Ídem.
B39: Múltiplo EV/EBITDA negocio — optimista | C39: 8 | D39: Ídem.
B40: Precio solicitado (terreno + negocio) | C40: 33000000 | D40: Precio de oferta.

Sheet Estado de Resultados
B2: Estado de Resultados
B3: Base operativa ajustada · MXN · Histórico no auditado; proyección con supuestos de la hoja Supuestos
B5: Concepto | C5: 2024 nov–dic | D5: 2025 ene–dic | E5: 2026 ene–may | F5: TTM jun-25–may-26 | H5: Año 1 jun-26–may-27 | I5: Año 2 jun-27–may-28 | J5: Año 3 jun-28–may-29
B6: Meses en el periodo | C6: 2 | D6: 12 | E6: 5 | F6: 12 | H6: 12 | I6: 12 | J6: 12
B8: INGRESOS
B9: Renta de canchas (incluye Hungers Escaleras) | C9: =SUM('Base Mensual'!C7:D7) -> 177236.85 | D9: =SUM('Base Mensual'!E7:P7) -> 1317468 | E9: =SUM('Base Mensual'!Q7:U7) -> 566149.02 | F9: =SUM('Base Mensual'!J7:U7) -> 1359417 | H9: =$F9*(1+Supuestos!$C$13)^1 -> 1515750 | I9: =$F9*(1+Supuestos!$C$13)^2 -> 1690061.2 | J9: =$F9*(1+Supuestos!$C$13)^3 -> 1884418.3
B10: Academia (clases) | C10: =SUM('Base Mensual'!C8:D8) -> 19400 | D10: =SUM('Base Mensual'!E8:P8) -> 405500 | E10: =SUM('Base Mensual'!Q8:U8) -> 271300 | F10: =SUM('Base Mensual'!J8:U8) -> 548900 | H10: =$F10*(1+Supuestos!$C$13)^1 -> 612023.5 | I10: =$F10*(1+Supuestos!$C$13)^2 -> 682406.2 | J10: =$F10*(1+Supuestos!$C$13)^3 -> 760882.92
B11: Alimentos y bebidas (bebidas, cafetería, botana) | C11: =SUM('Base Mensual'!C9:D9)+SUM('Base Mensual'!C11:D11)+SUM('Base Mensual'!C12:D12) -> 28416 | D11: =SUM('Base Mensual'!E9:P9)+SUM('Base Mensual'!E11:P11)+SUM('Base Mensual'!E12:P12) -> 353305 | E11: =SUM('Base Mensual'!Q9:U9)+SUM('Base Mensual'!Q11:U11)+SUM('Base Mensual'!Q12:U12) -> 166012.43 | F11: =SUM('Base Mensual'!J9:U9)+SUM('Base Mensual'!J11:U11)+SUM('Base Mensual'!J12:U12) -> 407412.43 | H11: =$F11*(1+Supuestos!$C$13)^1 -> 454264.86 | I11: =$F11*(1+Supuestos!$C$13)^2 -> 506505.32 | J11: =$F11*(1+Supuestos!$C$13)^3 -> 564753.43
B12: Pro-shop (pelotas, grips, palas, sacos) | C12: =SUM('Base Mensual'!C10:D10)+SUM('Base Mensual'!C13:D13)+SUM('Base Mensual'!C14:D14) -> 18394 | D12: =SUM('Base Mensual'!E10:P10)+SUM('Base Mensual'!E13:P13)+SUM('Base Mensual'!E14:P14) -> 168057 | E12: =SUM('Base Mensual'!Q10:U10)+SUM('Base Mensual'!Q13:U13)+SUM('Base Mensual'!Q14:U14) -> 77444.28 | F12: =SUM('Base Mensual'!J10:U10)+SUM('Base Mensual'!J13:U13)+SUM('Base Mensual'!J14:U14) -> 191687.28 | H12: =$F12*(1+Supuestos!$C$13)^1 -> 213731.32 | I12: =$F12*(1+Supuestos!$C$13)^2 -> 238310.42 | J12: =$F12*(1+Supuestos!$C$13)^3 -> 265716.12
B13: Total ingresos | C13: =SUM(C9:C12) -> 243446.85 | D13: =SUM(D9:D12) -> 2244330 | E13: =SUM(E9:E12) -> 1080905.7 | F13: =SUM(F9:F12) -> 2507416.7 | H13: =SUM(H9:H12) -> 2795769.7 | I13: =SUM(I9:I12) -> 3117283.2 | J13: =SUM(J9:J12) -> 3475770.7
B14: Ingreso promedio mensual | C14: =C13/C6 -> 121723.43 | D14: =D13/D6 -> 187027.5 | E14: =E13/E6 -> 216181.15 | F14: =F13/F6 -> 208951.39 | H14: =H13/H6 -> 232980.8 | I14: =I13/I6 -> 259773.6 | J14: =J13/J6 -> 289647.56
B15: Crecimiento anual de ingresos | H15: =H13/F13-1 -> 0.115 | I15: =I13/H13-1 -> 0.115 | J15: =J13/I13-1 -> 0.115
B17: COSTOS DIRECTOS
B18: Costo de mercancía (A&B, pro-shop, insumos, merch) | C18: =SUM('Base Mensual'!C23:D23)+SUM('Base Mensual'!C26:D26)+SUM('Base Mensual'!C30:D30) -> 22098.69 | D18: =SUM('Base Mensual'!E23:P23)+SUM('Base Mensual'!E26:P26)+SUM('Base Mensual'!E30:P30) -> 248434.42 | E18: =SUM('Base Mensual'!Q23:U23)+SUM('Base Mensual'!Q26:U26)+SUM('Base Mensual'!Q30:U30) -> 135267.8 | F18: =SUM('Base Mensual'!J23:U23)+SUM('Base Mensual'!J26:U26)+SUM('Base Mensual'!J30:U30) -> 297532.22 | H18: =$F18*(1+Supuestos!$C$13)^1 -> 331748.43 | I18: =$F18*(1+Supuestos!$C$13)^2 -> 369899.49 | J18: =$F18*(1+Supuestos!$C$13)^3 -> 412437.94
B19: Comisiones de entrenadores (50% de academia) | C19: =SUM('Base Mensual'!C31:D31) -> 12692 | D19: =SUM('Base Mensual'!E31:P31) -> 148424.75 | E19: =SUM('Base Mensual'!Q31:U31) -> 143654 | F19: =SUM('Base Mensual'!J31:U31) -> 249871.75 | H19: =$F19*(1+Supuestos!$C$13)^1 -> 278607 | I19: =$F19*(1+Supuestos!$C$13)^2 -> 310646.81 | J19: =$F19*(1+Supuestos!$C$13)^3 -> 346371.19
B20: Utilidad bruta (contribución) | C20: =C13-C18-C19 -> 208656.16 | D20: =D13-D18-D19 -> 1847470.8 | E20: =E13-E18-E19 -> 801983.93 | F20: =F13-F18-F19 -> 1960012.8 | H20: =H13-H18-H19 -> 2185414.2 | I20: =I13-I18-I19 -> 2436736.9 | J20: =J13-J18-J19 -> 2716961.6
B21: Margen de contribución | C21: =IF(C13=0,0,C20/C13) -> 0.85709123 | D21: =IF(D13=0,0,D20/D13) -> 0.82317254 | E21: =IF(E13=0,0,E20/E13) -> 0.74195548 | F21: =IF(F13=0,0,F20/F13) -> 0.78168608 | H21: =IF(H13=0,0,H20/H13) -> 0.78168608 | I21: =IF(I13=0,0,I20/I13) -> 0.78168608 | J21: =IF(J13=0,0,J20/J13) -> 0.78168608
B23: GASTOS DE OPERACIÓN
B24: Nómina operativa (recepción, gerente, bonos) | C24: =SUM('Base Mensual'!C24:D24)+SUM('Base Mensual'!C19:D19)+SUM('Base Mensual'!C34:D34) -> 34000 | D24: =SUM('Base Mensual'!E24:P24)+SUM('Base Mensual'!E19:P19)+SUM('Base Mensual'!E34:P34) -> 324598 | E24: =SUM('Base Mensual'!Q24:U24)+SUM('Base Mensual'!Q19:U19)+SUM('Base Mensual'!Q34:U34) -> 170560 | F24: =SUM('Base Mensual'!J24:U24)+SUM('Base Mensual'!J19:U19)+SUM('Base Mensual'!J34:U34) -> 365758 | H24: =$F24*(1+Supuestos!$C$13)^1 -> 407820.17 | I24: =$F24*(1+Supuestos!$C$13)^2 -> 454719.49 | J24: =$F24*(1+Supuestos!$C$13)^3 -> 507012.23
B25: Mantenimiento, reparaciones y mejoras | C25: =SUM('Base Mensual'!C28:D28)+SUM('Base Mensual'!C20:D20)+SUM('Base Mensual'!C29:D29) -> 40333 | D25: =SUM('Base Mensual'!E28:P28)+SUM('Base Mensual'!E20:P20)+SUM('Base Mensual'!E29:P29) -> 124128 | E25: =SUM('Base Mensual'!Q28:U28)+SUM('Base Mensual'!Q20:U20)+SUM('Base Mensual'!Q29:U29) -> 42727.7 | F25: =SUM('Base Mensual'!J28:U28)+SUM('Base Mensual'!J20:U20)+SUM('Base Mensual'!J29:U29) -> 97485.7 | H25: =$F25*(1+Supuestos!$C$13)^1 -> 108696.56 | I25: =$F25*(1+Supuestos!$C$13)^2 -> 121196.66 | J25: =$F25*(1+Supuestos!$C$13)^3 -> 135134.28
B26: Limpieza (general y vidrios) | C26: =SUM('Base Mensual'!C27:D27)+SUM('Base Mensual'!C22:D22) -> 7660 | D26: =SUM('Base Mensual'!E27:P27)+SUM('Base Mensual'!E22:P22) -> 63950 | E26: =SUM('Base Mensual'!Q27:U27)+SUM('Base Mensual'!Q22:U22) -> 14509.1 | F26: =SUM('Base Mensual'!J27:U27)+SUM('Base Mensual'!J22:U22) -> 52589.1 | H26: =$F26*(1+Supuestos!$C$13)^1 -> 58636.846 | I26: =$F26*(1+Supuestos!$C$13)^2 -> 65380.084 | J26: =$F26*(1+Supuestos!$C$13)^3 -> 72898.793
B27: Servicios (energía, agua, internet) | C27: =SUM('Base Mensual'!C33:D33) -> 10134 | D27: =SUM('Base Mensual'!E33:P33) -> 97444 | E27: =SUM('Base Mensual'!Q33:U33) -> 39260 | F27: =SUM('Base Mensual'!J33:U33) -> 116397 | H27: =$F27*(1+Supuestos!$C$13)^1 -> 129782.65 | I27: =$F27*(1+Supuestos!$C$13)^2 -> 144707.66 | J27: =$F27*(1+Supuestos!$C$13)^3 -> 161349.04
B28: Honorarios profesionales (legal y contable) | C28: =SUM('Base Mensual'!C18:D18)+SUM('Base Mensual'!C21:D21) -> 0 | D28: =SUM('Base Mensual'!E18:P18)+SUM('Base Mensual'!E21:P21) -> 36540 | E28: =SUM('Base Mensual'!Q18:U18)+SUM('Base Mensual'!Q21:U21) -> 94131.64 | F28: =SUM('Base Mensual'!J18:U18)+SUM('Base Mensual'!J21:U21) -> 130671.64 | H28: =$F28*(1+Supuestos!$C$13)^1 -> 145698.88 | I28: =$F28*(1+Supuestos!$C$13)^2 -> 162454.25 | J28: =$F28*(1+Supuestos!$C$13)^3 -> 181136.49
B29: Gastos generales y publicidad | C29: =SUM('Base Mensual'!C25:D25)+SUM('Base Mensual'!C32:D32) -> 13232 | D29: =SUM('Base Mensual'!E25:P25)+SUM('Base Mensual'!E32:P32) -> 198675 | E29: =SUM('Base Mensual'!Q25:U25)+SUM('Base Mensual'!Q32:U32) -> 7200 | F29: =SUM('Base Mensual'!J25:U25)+SUM('Base Mensual'!J32:U32) -> 108534 | H29: =$F29*(1+Supuestos!$C$13)^1 -> 121015.41 | I29: =$F29*(1+Supuestos!$C$13)^2 -> 134932.18 | J29: =$F29*(1+Supuestos!$C$13)^3 -> 150449.38
B30: Total gastos de operación | C30: =SUM(C24:C29) -> 105359 | D30: =SUM(D24:D29) -> 845335 | E30: =SUM(E24:E29) -> 368388.44 | F30: =SUM(F24:F29) -> 871435.44 | H30: =SUM(H24:H29) -> 971650.52 | I30: =SUM(I24:I29) -> 1083390.3 | J30: =SUM(J24:J29) -> 1207980.2
B32: EBITDA OPERATIVO AJUSTADO | C32: =C20-C30 -> 103297.16 | D32: =D20-D30 -> 1002135.8 | E32: =E20-E30 -> 433595.49 | F32: =F20-F30 -> 1088577.3 | H32: =H20-H30 -> 1213763.7 | I32: =I20-I30 -> 1353346.5 | J32: =J20-J30 -> 1508981.4
B33: Margen EBITDA | C33: =IF(C13=0,0,C32/C13) -> 0.42431093 | D33: =IF(D13=0,0,D32/D13) -> 0.44651893 | E33: =IF(E13=0,0,E32/E13) -> 0.40114089 | F33: =IF(F13=0,0,F32/F13) -> 0.43414296 | H33: =IF(H13=0,0,H32/H13) -> 0.43414296 | I33: =IF(I13=0,0,I32/I13) -> 0.43414296 | J33: =IF(J13=0,0,J32/J13) -> 0.43414296
B35: Depreciación (pro forma) | C35: =-C6*Supuestos!$C$9 -> -152135.4 | D35: =-D6*Supuestos!$C$9 -> -912812.4 | E35: =-E6*Supuestos!$C$9 -> -380338.5 | F35: =-F6*Supuestos!$C$9 -> -912812.4 | H35: =-12*Supuestos!$C$9-0*Supuestos!$C$8 -> -912812.4 | I35: =-12*Supuestos!$C$9-(-'Flujo de Efectivo'!I15)*Supuestos!$C$8 -> -921199.71 | J35: =-12*Supuestos!$C$9-(-'Flujo de Efectivo'!I15+-'Flujo de Efectivo'!J15)*Supuestos!$C$8 -> -930551.56
B36: UTILIDAD DE OPERACIÓN (EBIT) | C36: =C32+C35 -> -48838.24 | D36: =D32+D35 -> 89323.43 | E36: =E32+E35 -> 53256.99 | F36: =F32+F35 -> 175764.92 | H36: =H32+H35 -> 300951.31 | I36: =I32+I35 -> 432146.83 | J36: =J32+J35 -> 578429.83
B37: Margen de operación | C37: =IF(C13=0,0,C36/C13) -> -0.20061151 | D37: =IF(D13=0,0,D36/D13) -> 0.039799597 | E37: =IF(E13=0,0,E36/E13) -> 0.049270707 | F37: =IF(F13=0,0,F36/F13) -> 0.070098009 | H37: =IF(H13=0,0,H36/H13) -> 0.10764525 | I37: =IF(I13=0,0,I36/I13) -> 0.13862931 | J37: =IF(J13=0,0,J36/J13) -> 0.16641772
B38: ISR pro forma | C38: =-MAX(0,C36)*Supuestos!$C$11 -> 0 | D38: =-MAX(0,D36)*Supuestos!$C$11 -> -26797.029 | E38: =-MAX(0,E36)*Supuestos!$C$11 -> -15977.097 | F38: =-MAX(0,F36)*Supuestos!$C$11 -> -52729.476 | H38: =-MAX(0,H36)*Supuestos!$C$11 -> -90285.394 | I38: =-MAX(0,I36)*Supuestos!$C$11 -> -129644.05 | J38: =-MAX(0,J36)*Supuestos!$C$11 -> -173528.95
B39: UTILIDAD NETA PRO FORMA | C39: =C36+C38 -> -48838.24 | D39: =D36+D38 -> 62526.401 | E39: =E36+E38 -> 37279.893 | F39: =F36+F38 -> 123035.44 | H39: =H36+H38 -> 210665.92 | I39: =I36+I38 -> 302502.78 | J39: =J36+J38 -> 404900.88
B40: Margen neto | C40: =IF(C13=0,0,C39/C13) -> -0.20061151 | D40: =IF(D13=0,0,D39/D13) -> 0.027859718 | E40: =IF(E13=0,0,E39/E13) -> 0.034489495 | F40: =IF(F13=0,0,F39/F13) -> 0.049068606 | H40: =IF(H13=0,0,H39/H13) -> 0.075351672 | I40: =IF(I13=0,0,I39/I13) -> 0.09704052 | J40: =IF(J13=0,0,J39/J13) -> 0.1164924
B43: PUENTE: UTILIDAD SEGÚN REGISTROS DEL PROPIETARIO → EBITDA OPERATIVO AJUSTADO
B44: Utilidad según registros del propietario (antes de retiros) | C44: =SUM('Base Mensual'!C15:D15)+SUM('Base Mensual'!C45:D45)-SUM('Base Mensual'!C35:D35)-SUM('Base Mensual'!C46:D46)-SUM('Base Mensual'!C39:D39)-SUM('Base Mensual'!C43:D43) -> 46383.16 | D44: =SUM('Base Mensual'!E15:P15)+SUM('Base Mensual'!E45:P45)-SUM('Base Mensual'!E35:P35)-SUM('Base Mensual'!E46:P46)-SUM('Base Mensual'!E39:P39)-SUM('Base Mensual'!E43:P43) -> 467818.83 | E44: =SUM('Base Mensual'!Q15:U15)+SUM('Base Mensual'!Q45:U45)-SUM('Base Mensual'!Q35:U35)-SUM('Base Mensual'!Q46:U46)-SUM('Base Mensual'!Q39:U39)-SUM('Base Mensual'!Q43:U43) -> 229263.04 | F44: =SUM('Base Mensual'!J15:U15)+SUM('Base Mensual'!J45:U45)-SUM('Base Mensual'!J35:U35)-SUM('Base Mensual'!J46:U46)-SUM('Base Mensual'!J39:U39)-SUM('Base Mensual'!J43:U43) -> 499519.87
B45: (+) Gastos personales de los socios pagados por el club | C45: =SUM('Base Mensual'!C43:D43) -> 56914 | D45: =SUM('Base Mensual'!E43:P43) -> 534317 | E45: =SUM('Base Mensual'!Q43:U43) -> 0 | F45: =SUM('Base Mensual'!J43:U43) -> 384725
B46: (+) Sueldo del Director General (propietario saliente) | C46: =SUM('Base Mensual'!C39:D39) -> 0 | D46: =SUM('Base Mensual'!E39:P39) -> 0 | E46: =SUM('Base Mensual'!Q39:U39) -> 204332.45 | F46: =SUM('Base Mensual'!J39:U39) -> 204332.45
B47: (±) Fondo Apapacho neto (recaudación de terceros) | C47: =SUM('Base Mensual'!C46:D46)-SUM('Base Mensual'!C45:D45) -> 0 | D47: =SUM('Base Mensual'!E46:P46)-SUM('Base Mensual'!E45:P45) -> 0 | E47: =SUM('Base Mensual'!Q46:U46)-SUM('Base Mensual'!Q45:U45) -> 0 | F47: =SUM('Base Mensual'!J46:U46)-SUM('Base Mensual'!J45:U45) -> 0
B48: (=) EBITDA operativo ajustado | C48: =SUM(C44:C47) -> 103297.16 | D48: =SUM(D44:D47) -> 1002135.8 | E48: =SUM(E44:E47) -> 433595.49 | F48: =SUM(F44:F47) -> 1088577.3
B49: Verificación (debe ser cero) | C49: =C48-C32 -> 0 | D49: =D48-D32 -> 0 | E49: =E48-E32 -> 0 | F49: =F48-F32 -> 0
...

Sheet Balance General
B2: Balance General
B3: El Arroyo Investments, S.A.P. de I. de C.V. (operadora) · MXN · No auditado · El terreno (Promotora Goya, S.A. de C.V.) se presenta por separado en la hoja Valuación
B5: Concepto | C5: 30-abr-2026 último corte | D5: 31-may-2026 estimado | F5: may-2027 Año 1 | G5: may-2028 Año 2 | H5: may-2029 Año 3
B6: ACTIVO
B7: Efectivo y equivalentes | C7: =Supuestos!$C$30 -> 467498 | D7: =C7+'Base Mensual'!U36-'Base Mensual'!U39-'Base Mensual'!U43+'Base Mensual'!U45-'Base Mensual'!U46-Supuestos!$C$22 -> 519436.07 | F7: =D7+'Flujo de Efectivo'!I25 -> 1559041.3 | G7: =F7+'Flujo de Efectivo'!J25 -> 2689225.3 | H7: =G7+'Flujo de Efectivo'!K25 -> 3920404.6
B8: Inventarios | C8: =Supuestos!$C$18 -> 0 | D8: =Supuestos!$C$18 -> 0 | F8: =D8+Supuestos!$C$16 -> 0 | G8: =F8+Supuestos!$C$16 -> 0 | H8: =G8+Supuestos!$C$16 -> 0
B9: Total activo circulante | C9: =SUM(C7:C8) -> 467498 | D9: =SUM(D7:D8) -> 519436.07 | F9: =SUM(F7:F8) -> 1559041.3 | G9: =SUM(G7:G8) -> 2689225.3 | H9: =SUM(H7:H8) -> 3920404.6
B11: Instalaciones, canchas y equipo (costo) | C11: =Supuestos!$C$7 -> 9128124 | D11: =Supuestos!$C$7 -> 9128124 | F11: =D11-'Flujo de Efectivo'!I15 -> 9211997.1 | G11: =F11-'Flujo de Efectivo'!J15 -> 9305515.6 | H11: =G11-'Flujo de Efectivo'!K15 -> 9409788.7
B12: (−) Depreciación acumulada (pro forma) | C12: =-18*Supuestos!$C$9 -> -1369218.6 | D12: =-19*Supuestos!$C$9 -> -1445286.3 | F12: =D12+'Estado de Resultados'!H35 -> -2358098.7 | G12: =F12+'Estado de Resultados'!I35 -> -3279298.4 | H12: =G12+'Estado de Resultados'!J35 -> -4209850
B13: Activo fijo neto | C13: =C11+C12 -> 7758905.4 | D13: =D11+D12 -> 7682837.7 | F13: =F11+F12 -> 6853898.4 | G13: =G11+G12 -> 6026217.2 | H13: =H11+H12 -> 5199938.7
B15: TOTAL ACTIVO | C15: =C9+C13 -> 8226403.4 | D15: =D9+D13 -> 8202273.8 | F15: =F9+F13 -> 8412939.7 | G15: =G9+G13 -> 8715442.5 | H15: =H9+H13 -> 9120343.4
B17: PASIVO
B18: Proveedores y acreedores | C18: =Supuestos!$C$19 -> 0 | D18: =Supuestos!$C$19 -> 0 | F18: =D18 -> 0 | G18: =F18 -> 0 | H18: =G18 -> 0
B19: Impuestos por pagar | C19: =Supuestos!$C$20 -> 0 | D19: =Supuestos!$C$20 -> 0 | F19: =D19 -> 0 | G19: =F19 -> 0 | H19: =G19 -> 0
B20: Deuda financiera | C20: =Supuestos!$C$21 -> 0 | D20: =Supuestos!$C$21 -> 0 | F20: =D20 -> 0 | G20: =F20 -> 0 | H20: =G20 -> 0
B21: TOTAL PASIVO | C21: =SUM(C18:C20) -> 0 | D21: =SUM(D18:D20) -> 0 | F21: =SUM(F18:F20) -> 0 | G21: =SUM(G18:G20) -> 0 | H21: =SUM(H18:H20) -> 0
B23: CAPITAL CONTABLE
B24: Capital aportado por los socios | C24: =Supuestos!$C$7 -> 9128124 | D24: =Supuestos!$C$7 -> 9128124 | F24: =D24 -> 9128124 | G24: =F24 -> 9128124 | H24: =G24 -> 9128124
B25: Resultados acumulados | C25: =SUM('Base Mensual'!C36:T36)-SUM('Base Mensual'!C39:T39)-18*Supuestos!$C$9 -> -86460.64 | D25: =SUM('Base Mensual'!C36:U36)-SUM('Base Mensual'!C39:U39)-19*Supuestos!$C$9 -> -110590.27 | F25: =D25+'Estado de Resultados'!H39 -> 100075.65 | G25: =F25+'Estado de Resultados'!I39 -> 402578.43 | H25: =G25+'Estado de Resultados'!J39 -> 807479.31
B26: (−) Distribuciones a socios acumuladas | C26: =-SUM('Base Mensual'!C43:T43)-SUM('Base Mensual'!C44:T44) -> -819231 | D26: =-SUM('Base Mensual'!C43:U43)-SUM('Base Mensual'!C44:U44)-Supuestos!$C$22 -> -819231 | F26: =D26+'Flujo de Efectivo'!I21 -> -819231 | G26: =F26+'Flujo de Efectivo'!J21 -> -819231 | H26: =G26+'Flujo de Efectivo'!K21 -> -819231
B27: Partida en conciliación de efectivo (ver Nota 6) | C27: =C15-C21-C24-C25-C26 -> 3971.04 | D27: =D15-D21-D24-D25-D26 -> 3971.04 | F27: =D27 -> 3971.04 | G27: =F27 -> 3971.04 | H27: =G27 -> 3971.04
B28: TOTAL CAPITAL CONTABLE | C28: =SUM(C24:C27) -> 8226403.4 | D28: =SUM(D24:D27) -> 8202273.8 | F28: =SUM(F24:F27) -> 8412939.7 | G28: =SUM(G24:G27) -> 8715442.5 | H28: =SUM(H24:H27) -> 9120343.4
B30: TOTAL PASIVO + CAPITAL | C30: =C21+C28 -> 8226403.4 | D30: =D21+D28 -> 8202273.8 | F30: =F21+F28 -> 8412939.7 | G30: =G21+G28 -> 8715442.5 | H30: =H21+H28 -> 9120343.4
B31: Verificación: activo − (pasivo + capital) = 0 | C31: =ROUND(C15-C30,2) -> 0 | D31: =ROUND(D15-D30,2) -> 0 | F31: =ROUND(F15-F30,2) -> 0 | G31: =ROUND(G15-G30,2) -> 0 | H31: =ROUND(H15-H30,2) -> 0
B33: INDICADORES
B34: Deuda neta (deuda − efectivo) | C34: =C20-C7 -> -467498 | D34: =D20-D7 -> -519436.07 | F34: =F20-F7 -> -1559041.3 | G34: =G20-G7 -> -2689225.3 | H34: =H20-H7 -> -3920404.6
B35: Pasivo total / capital contable | C35: =C21/C28 -> 0 | D35: =D21/D28 -> 0 | F35: =F21/F28 -> 0 | G35: =G21/G28 -> 0 | H35: =H21/H28 -> 0
B37: Notas: (1) El corte de abril usa los saldos bancarios y de caja reportados por el propietario; el 31-may-26 se estima con el flujo de mayo según registros. (2) Inventario, proveedores, impuestos por pagar y retiros de mayo están pendientes de confirmar (celdas amarillas en Supuestos) y hoy se muestran en cero. (3) La depreciación es pro forma (Nota 4). (4) El terreno no forma parte del balance de la operadora: pertenece a Promotora Goya, S.A. de C.V. y se valúa por separado (hoja Valuación). (5) La partida en conciliación es la diferencia entre el efectivo real y el que explican los registros (Nota 6); se mantiene constante en la proyección.

Sheet Flujo de Efectivo
B2: Estado de Flujo de Efectivo
B3: Método indirecto partiendo del EBITDA · MXN · Histórico desde la apertura; proyección años 1–3
B5: Concepto | C5: Pre-apertura | D5: 2024 nov–dic | E5: 2025 ene–dic | F5: 2026 ene–may | G5: Acumulado inicio–may-26 | I5: Año 1 | J5: Año 2 | K5: Año 3
B6: ACTIVIDADES DE OPERACIÓN
B7: EBITDA operativo ajustado | D7: ='Estado de Resultados'!C32 -> 103297.16 | E7: ='Estado de Resultados'!D32 -> 1002135.8 | F7: ='Estado de Resultados'!E32 -> 433595.49 | G7: =SUM(C7:F7) -> 1539028.5 | I7: ='Estado de Resultados'!H32 -> 1213763.7 | J7: ='Estado de Resultados'!I32 -> 1353346.5 | K7: ='Estado de Resultados'!J32 -> 1508981.4
B8: (−) Sueldo del Director General (propietario saliente) | D8: =-SUM('Base Mensual'!C39:D39) -> 0 | E8: =-SUM('Base Mensual'!E39:P39) -> 0 | F8: =-SUM('Base Mensual'!Q39:U39) -> -204332.45 | G8: =SUM(C8:F8) -> -204332.45 | I8: =0 -> 0 | J8: =0 -> 0 | K8: =0 -> 0
B9: (−) ISR pagado | D9: =0 -> 0 | E9: =0 -> 0 | F9: =0 -> 0 | G9: =SUM(C9:F9) -> 0 | I9: ='Estado de Resultados'!H38 -> -90285.394 | J9: ='Estado de Resultados'!I38 -> -129644.05 | K9: ='Estado de Resultados'!J38 -> -173528.95
B10: (±) Variación en capital de trabajo | D10: =0 -> 0 | E10: =0 -> 0 | F10: =0 -> 0 | G10: =SUM(C10:F10) -> 0 | I10: =-Supuestos!$C$16 -> 0 | J10: =-Supuestos!$C$16 -> 0 | K10: =-Supuestos!$C$16 -> 0
B11: Flujo neto de actividades de operación | C11: =SUM(C7:C10) -> 0 | D11: =SUM(D7:D10) -> 103297.16 | E11: =SUM(E7:E10) -> 1002135.8 | F11: =SUM(F7:F10) -> 229263.04 | G11: =SUM(C11:F11) -> 1334696 | I11: =SUM(I7:I10) -> 1123478.3 | J11: =SUM(J7:J10) -> 1223702.5 | K11: =SUM(K7:K10) -> 1335452.4
B13: ACTIVIDADES DE INVERSIÓN
B14: Inversión inicial en instalaciones y equipo | C14: =-Supuestos!$C$7 -> -9128124 | D14: =0 -> 0 | E14: =0 -> 0 | F14: =0 -> 0 | G14: =SUM(C14:F14) -> -9128124 | I14: =0 -> 0 | J14: =0 -> 0 | K14: =0 -> 0
B15: Capex de mantenimiento | D15: =0 -> 0 | E15: =0 -> 0 | F15: =0 -> 0 | G15: =SUM(C15:F15) -> 0 | I15: =-'Estado de Resultados'!H13*Supuestos!$C$14 -> -83873.09 | J15: =-'Estado de Resultados'!I13*Supuestos!$C$14 -> -93518.495 | K15: =-'Estado de Resultados'!J13*Supuestos!$C$14 -> -104273.12
B16: Flujo neto de actividades de inversión | C16: =SUM(C14:C15) -> -9128124 | D16: =SUM(D14:D15) -> 0 | E16: =SUM(E14:E15) -> 0 | F16: =SUM(F14:F15) -> 0 | G16: =SUM(C16:F16) -> -9128124 | I16: =SUM(I14:I15) -> -83873.09 | J16: =SUM(J14:J15) -> -93518.495 | K16: =SUM(K14:K15) -> -104273.12
B18: ACTIVIDADES DE FINANCIAMIENTO
B19: Aportaciones de capital de los socios | C19: =Supuestos!$C$7 -> 9128124 | D19: =0 -> 0 | E19: =0 -> 0 | F19: =0 -> 0 | G19: =SUM(C19:F19) -> 9128124 | I19: =0 -> 0 | J19: =0 -> 0 | K19: =0 -> 0
B20: Gastos personales de socios pagados por el club | D20: =-SUM('Base Mensual'!C43:D43) -> -56914 | E20: =-SUM('Base Mensual'!E43:P43) -> -534317 | F20: =-SUM('Base Mensual'!Q43:U43) -> 0 | G20: =SUM(C20:F20) -> -591231 | I20: =0 -> 0 | J20: =0 -> 0 | K20: =0 -> 0
B21: Retiros de utilidades de socios | D21: =-SUM('Base Mensual'!C44:D44) -> 0 | E21: =-SUM('Base Mensual'!E44:P44) -> -202000 | F21: =-SUM('Base Mensual'!Q44:U44) -> -26000 | G21: =SUM(C21:F21) -> -228000 | I21: =-MAX(0,'Estado de Resultados'!H39)*Supuestos!$C$15 -> 0 | J21: =-MAX(0,'Estado de Resultados'!I39)*Supuestos!$C$15 -> 0 | K21: =-MAX(0,'Estado de Resultados'!J39)*Supuestos!$C$15 -> 0
B22: Fondo Apapacho (recaudado y entregado a la fundación, neto) | D22: =SUM('Base Mensual'!C45:D45)-SUM('Base Mensual'!C46:D46) -> 0 | E22: =SUM('Base Mensual'!E45:P45)-SUM('Base Mensual'!E46:P46) -> 0 | F22: =SUM('Base Mensual'!Q45:U45)-SUM('Base Mensual'!Q46:U46) -> 0 | G22: =SUM(C22:F22) -> 0 | I22: =0 -> 0 | J22: =0 -> 0 | K22: =0 -> 0
B23: Flujo neto de actividades de financiamiento | C23: =SUM(C19:C22) -> 9128124 | D23: =SUM(D19:D22) -> -56914 | E23: =SUM(E19:E22) -> -736317 | F23: =SUM(F19:F22) -> -26000 | G23: =SUM(C23:F23) -> 8308893 | I23: =SUM(I19:I22) -> 0 | J23: =SUM(J19:J22) -> 0 | K23: =SUM(K19:K22) -> 0
B25: VARIACIÓN NETA DE EFECTIVO | C25: =C11+C16+C23 -> 0 | D25: =D11+D16+D23 -> 46383.16 | E25: =E11+E16+E23 -> 265818.83 | F25: =F11+F16+F23 -> 203263.04 | G25: =SUM(C25:F25) -> 515465.03 | I25: =I11+I16+I23 -> 1039605.2 | J25: =J11+J16+J23 -> 1130184 | K25: =K11+K16+K23 -> 1231179.3
B26: Efectivo al inicio del periodo | C26: 0 | D26: =C27 -> 0 | E26: =D27 -> 46383.16 | F26: =E27 -> 312201.99 | G26: =C26 -> 0 | I26: ='Balance General'!D7 -> 519436.07 | J26: =I27 -> 1559041.3 | K26: =J27 -> 2689225.3
B27: Efectivo al final del periodo | C27: =C26+C25 -> 0 | D27: =D26+D25 -> 46383.16 | E27: =E26+E25 -> 312201.99 | F27: =F26+F25 -> 515465.03 | G27: =G26+G25 -> 515465.03 | I27: =I26+I25 -> 1559041.3 | J27: =J26+J25 -> 2689225.3 | K27: =K26+K25 -> 3920404.6
I28: Año 1 inicia con el efectivo del balance estimado al 31-may-26 (incluye la partida en conciliación).
B29: MEMO — CONCILIACIÓN CONTRA SALDOS BANCARIOS (CORTE ABRIL 2026)
B30: Efectivo según registros acumulados al cierre de abril 2026 | G30: ='Base Mensual'!T50 -> 463526.96
B31: Efectivo real en cuentas y caja (último corte reportado) | G31: =Supuestos!$C$30 -> 467498
B32: Diferencia: real − registros (positivo = sobra efectivo) | G32: =G31-G30 -> 3971.04
B33: Diferencia como % del flujo de operación acumulado | G33: =G32/G11 -> 0.0029752392
B35: La diferencia considera abril completo según registros. Si el corte de saldos se tomó a mitad de mes (lo que sugiere la hoja del propietario), la diferencia sería mayor y en el mismo sentido: en todos los cortes disponibles el efectivo real ha sido mayor al que explican los registros, nunca menor. Ver Nota 6 y Reporte_Financiero.xlsx, hoja Conciliación de Caja.
B37: FLUJO DE EFECTIVO LIBRE PRO FORMA PARA EL COMPRADOR
G38: TTM | I38: Año 1 | J38: Año 2 | K38: Año 3
B39: EBITDA operativo ajustado | G39: ='Estado de Resultados'!F32 -> 1088577.3 | I39: ='Estado de Resultados'!H32 -> 1213763.7 | J39: ='Estado de Resultados'!I32 -> 1353346.5 | K39: ='Estado de Resultados'!J32 -> 1508981.4
B40: (−) ISR pro forma | G40: ='Estado de Resultados'!F38 -> -52729.476 | I40: ='Estado de Resultados'!H38 -> -90285.394 | J40: ='Estado de Resultados'!I38 -> -129644.05 | K40: ='Estado de Resultados'!J38 -> -173528.95
B41: (−) Capex de mantenimiento | G41: =-'Estado de Resultados'!F13*Supuestos!$C$14 -> -75222.502 | I41: =I15 -> -83873.09 | J41: =J15 -> -93518.495 | K41: =K15 -> -104273.12
B42: (±) Capital de trabajo | G42: =-Supuestos!$C$16 -> 0 | I42: =I10 -> 0 | J42: =J10 -> 0 | K42: =K10 -> 0
B43: (=) Flujo de efectivo libre (FCF) | G43: =SUM(G39:G42) -> 960625.34 | I43: =SUM(I39:I42) -> 1039605.2 | J43: =SUM(J39:J42) -> 1130184 | K43: =SUM(K39:K42) -> 1231179.3
B44: Conversión de EBITDA a FCF | G44: =G43/G39 -> 0.88245945 | I44: =I43/I39 -> 0.85651368 | J44: =J43/J39 -> 0.83510318 | K44: =K43/K39 -> 0.81590093
B45: FCF / precio solicitado (rendimiento en efectivo) | G45: =G43/Supuestos!$C$40 -> 0.029109859 | I45: =I43/Supuestos!$C$40 -> 0.031503189 | J45: =J43/Supuestos!$C$40 -> 0.034248 | K45: =K43/Supuestos!$C$40 -> 0.037308464

Sheet Valuación
B2: Valuación — Terreno + Negocio
B3: Suma de partes: valor del terreno por comparables + valor del negocio por múltiplo de EBITDA TTM · MXN
B5: Concepto | C5: Conservador | D5: Base | E5: Optimista
B6: Superficie del terreno (m²) | C6: =Supuestos!$C$33 -> 3762 | D6: =Supuestos!$C$33 -> 3762 | E6: =Supuestos!$C$33 -> 3762
B7: Valor de tierra ($/m²) | C7: =Supuestos!$C$34 -> 7000 | D7: =Supuestos!$C$35 -> 8000 | E7: =Supuestos!$C$36 -> 9500
B8: Valor del terreno | C8: =C6*C7 -> 26334000 | D8: =D6*D7 -> 30096000 | E8: =E6*E7 -> 35739000
B10: EBITDA operativo ajustado TTM | C10: ='Estado de Resultados'!$F$32 -> 1088577.3 | D10: ='Estado de Resultados'!$F$32 -> 1088577.3 | E10: ='Estado de Resultados'!$F$32 -> 1088577.3
B11: Múltiplo EV/EBITDA | C11: =Supuestos!$C$37 -> 5 | D11: =Supuestos!$C$38 -> 6.5 | E11: =Supuestos!$C$39 -> 8
B12: Valor del negocio en operación | C12: =C10*C11 -> 5442886.6 | D12: =D10*D11 -> 7075752.6 | E12: =E10*E11 -> 8708618.6
B14: VALOR COMBINADO (terreno + negocio) | C14: =C8+C12 -> 31776887 | D14: =D8+D12 -> 37171753 | E14: =E8+E12 -> 44447619
B15: (+) Efectivo de la operadora (31-may-26 est.) | C15: ='Balance General'!$D$7 -> 519436.07 | D15: ='Balance General'!$D$7 -> 519436.07 | E15: ='Balance General'!$D$7 -> 519436.07
B16: (−) Deuda financiera | C16: =-'Balance General'!$D$20 -> 0 | D16: =-'Balance General'!$D$20 -> 0 | E16: =-'Balance General'!$D$20 -> 0
B17: (=) Valor del capital (equity value) | C17: =SUM(C14:C16) -> 32296323 | D17: =SUM(D14:D16) -> 37691189 | E17: =SUM(E14:E16) -> 44967055
B19: Precio solicitado | C19: =Supuestos!$C$40 -> 33000000 | D19: =Supuestos!$C$40 -> 33000000 | E19: =Supuestos!$C$40 -> 33000000
B20: Precio vs. valor combinado | C20: =C19/C14-1 -> 0.038490662 | D20: =D19/D14-1 -> -0.11222911 | E20: =E19/E14-1 -> -0.25755302
B21: Múltiplo implícito del negocio al precio solicitado | C21: =IF(C19<C8,"Precio < terreno",(C19-C8)/C10) -> 6.1235889 | D21: =IF(D19<D8,"Precio < terreno",(D19-D8)/D10) -> 2.6677021 | E21: =IF(E19<E8,"Precio < terreno",(E19-E8)/E10) -> Precio < terreno
B22: Múltiplo precio / EBITDA TTM (incluye terreno) | C22: =C19/C10 -> 30.314797 | D22: =D19/D10 -> 30.314797 | E22: =E19/E10 -> 30.314797
B24: Lectura: al precio solicitado y descontando el valor del terreno, el comprador paga por el negocio en operación el múltiplo implícito indicado. Los valores de tierra provienen del Estudio de Valuación Inmobiliaria (comparables de mercado); no sustituyen un avalúo profesional. El efectivo de la operadora se muestra como referencia: su tratamiento (incluido o retirado antes del cierre) se define en la negociación.
B26: RETORNO ILUSTRATIVO PARA EL COMPRADOR (3 AÑOS, SIN APALANCAMIENTO)
B27: Compra a precio solicitado al inicio del Año 1; recibe el FCF pro forma de los años 1–3; al final del Año 3 el activo vale: terreno a valor de tierra del escenario (sin plusvalía) + negocio al múltiplo del escenario sobre el EBITDA del Año 3. Ilustrativo — no es una promesa de rendimiento.
B28: Flujo (MXN) | C28: Conservador | D28: Base | E28: Optimista
B29: Año 0 — precio de compra | C29: =-Supuestos!$C$40 -> -33000000 | D29: =-Supuestos!$C$40 -> -33000000 | E29: =-Supuestos!$C$40 -> -33000000
B30: Año 1 — FCF | C30: ='Flujo de Efectivo'!$I$43 -> 1039605.2 | D30: ='Flujo de Efectivo'!$I$43 -> 1039605.2 | E30: ='Flujo de Efectivo'!$I$43 -> 1039605.2
B31: Año 2 — FCF | C31: ='Flujo de Efectivo'!$J$43 -> 1130184 | D31: ='Flujo de Efectivo'!$J$43 -> 1130184 | E31: ='Flujo de Efectivo'!$J$43 -> 1130184
B32: Año 3 — FCF + valor de salida | C32: ='Flujo de Efectivo'!$K$43+C8+C11*'Estado de Resultados'!$J$32 -> 35110086 | D32: ='Flujo de Efectivo'!$K$43+D8+D11*'Estado de Resultados'!$J$32 -> 41135558 | E32: ='Flujo de Efectivo'!$K$43+E8+E11*'Estado de Resultados'!$J$32 -> 49042030
B33: TIR (anual) | C33: =IRR(C29:C32) -> 0.042780859 | D33: =IRR(D29:D32) -> 0.097534023 | E33: =IRR(E29:E32) -> 0.16186603
B34: Múltiplo sobre lo invertido (MOIC) | C34: =SUM(C30:C32)/-C29 -> 1.1296932 | D34: =SUM(D30:D32)/-D29 -> 1.3122833 | E34: =SUM(E30:E32)/-E29 -> 1.5518733
B36: SENSIBILIDAD DE LA TIR — valor de tierra ($/m²) vs. múltiplo de salida
B37: $/m² \ múltiplo de salida | C37: =Supuestos!$C$37 -> 5 | D37: =Supuestos!$C$38 -> 6.5 | E37: =Supuestos!$C$39 -> 8
B38: =Supuestos!$C$34 -> 7000 | C38: =IRR(I38:L38) -> 0.042780859 | D38: =IRR(N38:Q38) -> 0.064026231 | E38: =IRR(S38:V38) -> 0.084439328 | I38: =-Supuestos!$C$40 -> -33000000 | J38: ='Flujo de Efectivo'!$I$43 -> 1039605.2 | K38: ='Flujo de Efectivo'!$J$43 -> 1130184 | L38: ='Flujo de Efectivo'!$K$43+$B38*Supuestos!$C$33+C$37*'Estado de Resultados'!$J$32 -> 35110086 | N38: =-Supuestos!$C$40 -> -33000000 | O38: ='Flujo de Efectivo'!$I$43 -> 1039605.2 | P38: ='Flujo de Efectivo'!$J$43 -> 1130184 | Q38: ='Flujo de Efectivo'!$K$43+$B38*Supuestos!$C$33+D$37*'Estado de Resultados'!$J$32 -> 37373558 | S38: =-Supuestos!$C$40 -> -33000000 | T38: ='Flujo de Efectivo'!$I$43 -> 1039605.2 | U38: ='Flujo de Efectivo'!$J$43 -> 1130184 | V38: ='Flujo de Efectivo'!$K$43+$B38*Supuestos!$C$33+E$37*'Estado de Resultados'!$J$32 -> 39637030
B39: =Supuestos!$C$35 -> 8000 | C39: =IRR(I39:L39) -> 0.077628765 | D39: =IRR(N39:Q39) -> 0.097534023 | E39: =IRR(S39:V39) -> 0.11672914 | I39: =-Supuestos!$C$40 -> -33000000 | J39: ='Flujo de Efectivo'!$I$43 -> 1039605.2 | K39: ='Flujo de Efectivo'!$J$43 -> 1130184 | L39: ='Flujo de Efectivo'!$K$43+$B39*Supuestos!$C$33+C$37*'Estado de Resultados'!$J$32 -> 38872086 | N39: =-Supuestos!$C$40 -> -33000000 | O39: ='Flujo de Efectivo'!$I$43 -> 1039605.2 | P39: ='Flujo de Efectivo'!$J$43 -> 1130184 | Q39: ='Flujo de Efectivo'!$K$43+$B39*Supuestos!$C$33+D$37*'Estado de Resultados'!$J$32 -> 41135558 | S39: =-Supuestos!$C$40 -> -33000000 | T39: ='Flujo de Efectivo'!$I$43 -> 1039605.2 | U39: ='Flujo de Efectivo'!$J$43 -> 1130184 | V39: ='Flujo de Efectivo'!$K$43+$B39*Supuestos!$C$33+E$37*'Estado de Resultados'!$J$32 -> 43399030
B40: =Supuestos!$C$36 -> 9500 | C40: =IRR(I40:L40) -> 0.12595106 | D40: =IRR(N40:Q40) -> 0.14419556 | E40: =IRR(S40:V40) -> 0.16186603 | I40: =-Supuestos!$C$40 -> -33000000 | J40: ='Flujo de Efectivo'!$I$43 -> 1039605.2 | K40: ='Flujo de Efectivo'!$J$43 -> 1130184 | L40: ='Flujo de Efectivo'!$K$43+$B40*Supuestos!$C$33+C$37*'Estado de Resultados'!$J$32 -> 44515086 | N40: =-Supuestos!$C$40 -> -33000000 | O40: ='Flujo de Efectivo'!$I$43 -> 1039605.2 | P40: ='Flujo de Efectivo'!$J$43 -> 1130184 | Q40: ='Flujo de Efectivo'!$K$43+$B40*Supuestos!$C$33+D$37*'Estado de Resultados'!$J$32 -> 46778558 | S40: =-Supuestos!$C$40 -> -33000000 | T40: ='Flujo de Efectivo'!$I$43 -> 1039605.2 | U40: ='Flujo de Efectivo'!$J$43 -> 1130184 | V40: ='Flujo de Efectivo'!$K$43+$B40*Supuestos!$C$33+E$37*'Estado de Resultados'!$J$32 -> 49042030
B42: Columnas auxiliares ocultas (I–W) contienen los flujos usados en cada celda de la sensibilidad.

Sheet Notas
B2: Notas a los Estados Financieros
B3: Forman parte integral de los estados financieros
B5: Nota 1 | C5: Entidad y perímetro
C6: Padel Palmira Club Deportivo es operado por El Arroyo Investments, S.A.P. de I. de C.V., titular de la Licencia de Funcionamiento 2026 (registro municipal 0007050010, giro: canchas de pádel y club campestre con venta de alimentos tipo snack). El terreno de 3,762 m² en Av. Palmira No. 58, Cuernavaca, pertenece a Promotora Goya, S.A. de C.V. La transacción ofrecida comprende terreno y negocio en conjunto; por ello el balance general presenta a la operadora y el terreno se valúa por separado en la hoja Valuación.
B8: Nota 2 | C8: Base de preparación
C9: Estados no auditados, preparados por la administración a partir de los registros internos del club (ventas Loyverse/Clip/Playtomic y bitácora de egresos), en pesos mexicanos. Periodo histórico: noviembre 2024 – mayo 2026 (19 meses). Los ingresos y egresos se reconocen en el mes en que se cobran o pagan (base de efectivo), lo que en este negocio es prácticamente equivalente a base devengada porque los clientes pagan al momento del servicio.
B11: Nota 3 | C11: Ajustes al resultado reportado
C12: Se excluyen del EBITDA operativo, una sola vez: (a) gastos personales de los socios pagados por el club en 2024-2025 (renta de vivienda, alimentación, transporte) — $591,231 acumulados; (b) sueldo del Director General (propietario saliente, $40,000 mensuales desde enero 2026), que no continúa tras la venta; el gerente contratado sí permanece y su sueldo se mantiene como gasto; (c) Fondo Apapacho, recaudación benéfica que se cobra y entrega íntegra a una fundación (neutral). El puente en el Estado de Resultados concilia la utilidad según registros con el EBITDA ajustado.
B14: Nota 4 | C14: Instalaciones y depreciación
C15: La inversión inicial del proyecto fue de $9,128,124 (dato del propietario), aportada por los socios antes de la apertura y sin financiamiento. Se asume que no incluye el terreno. El club no registra depreciación; para fines pro forma se aplica una tasa ponderada de 10% anual en línea recta desde noviembre 2024. Con el desglose real de la inversión (construcción al 5%, equipo al 10%) la depreciación probablemente sería menor y la utilidad de operación mayor.
B17: Nota 5 | C17: Impuestos
C18: Los registros del club no separan pagos de ISR ni IVA. El ISR mostrado es pro forma (30% sobre la utilidad de operación, régimen general de personas morales) para que el comprador evalúe resultados después de impuestos. No se modela PTU. La situación fiscal de la operadora (declaraciones, saldos a favor o a cargo) debe confirmarse con el contador como parte de la due diligence.
B20: Nota 6 | C20: Efectivo y conciliación
C21: Efectivo al último corte de abril 2026: $467,498 (Clip $111,744; BBVA $13,054; Nu $113,000; Ualá $103,000; Didi $26,700; caja $100,000). Partiendo de cero en noviembre 2024, el flujo según registros (EBITDA menos sueldo del director, gastos personales y retiros de socios) explica $463,527 al cierre de abril: diferencia de $3,971. Si el corte se tomó a mitad de mes, la diferencia es mayor (hasta ~$49,000) y en el mismo sentido; en todos los cortes disponibles desde mayo 2025 el efectivo real ha sido mayor al que explican los registros, nunca menor. La partida en conciliación del balance refleja esta diferencia. Recomendación para el comprador: cortes de caja formales al cierre de cada mes.
B23: Nota 7 | C23: Pasivos y contingencias
C24: Según el propietario, la operadora no tiene deuda financiera y el terreno está libre de gravámenes, sujeto a la entrega del certificado oficial de libertad de gravamen del Registro Público de la Propiedad. El predio es objeto de un juicio de lesividad promovido por el Ayuntamiento de Cuernavaca; el despacho que representa a Promotora Goya evalúa el riesgo como bajo. Los honorarios legales asociados (enero–febrero 2026) están incluidos en los gastos de operación. Inventario, proveedores e impuestos por pagar están pendientes de confirmar y se muestran en cero.
B26: Nota 8 | C26: Proyección
C27: Escenario orgánico de 3 años (junio 2026 – mayo 2029): ingresos crecen 11.5% anual (crecimiento documentado de horas de cancha ocupadas), costos crecen al mismo ritmo (margen constante), capex de mantenimiento de 3% de ingresos, ISR de 30% y sin distribuciones. No incluye la Fase 2 (alberca, cancha de tenis, casa club), cuyo potencial se describe cualitativamente en el documento de Operación y Expansión. Es una estimación, no una garantía de resultados.
B29: Nota 9 | C29: Eventos posteriores
C30: Las cifras históricas cubren hasta mayo 2026. Los meses posteriores se pondrán a disposición del comprador en la etapa de due diligence.

Sheet Base Mensual
B2: Base Mensual — Registros Operativos
B3: Fuente: estado de resultados interno del club (Loyverse, Clip, Playtomic, bitácora de gastos) vía Reporte_Financiero.xlsx, hoja "Datos Fuente". Texto azul = dato capturado.
B5: Concepto | C5: Nov-24 | D5: Dic-24 | E5: Ene-25 | F5: Feb-25 | G5: Mar-25 | H5: Abr-25 | I5: May-25 | J5: Jun-25 | K5: Jul-25 | L5: Ago-25 | M5: Sep-25 | N5: Oct-25 | O5: Nov-25 | P5: Dic-25 | Q5: Ene-26 | R5: Feb-26 | S5: Mar-26 | T5: Abr-26 | U5: May-26 | V5: Total 19m
B6: INGRESOS OPERATIVOS
B7: Cancha | C7: 81741.85 | D7: 95495 | E7: 99567 | F7: 93620 | G7: 109082 | H7: 120527 | I7: 101404 | J7: 113871 | K7: 120065 | L7: 120267 | M7: 110453 | N7: 119750 | O7: 101884 | P7: 106978 | Q7: 120974.57 | R7: 100805 | S7: 119721.28 | T7: 122406.17 | U7: 102242 | V7: =SUM(C7:U7) -> 2060853.9
B8: Clases | C8: 17000 | D8: 2400 | E8: 13200 | F8: 31200 | G8: 26500 | H8: 30400 | I8: 26600 | J8: 36350 | K8: 50500 | L8: 18500 | M8: 48025 | N8: 40225 | O8: 43600 | P8: 40400 | Q8: 49125 | R8: 46350 | S8: 51125 | T8: 61000 | U8: 63700 | V8: =SUM(C8:U8) -> 696200
B9: Bebidas | C9: 11020 | D9: 11936 | E9: 10435 | F9: 12510 | G9: 15730 | H9: 15405 | I9: 15320 | J9: 12260 | K9: 18330 | L9: 16475 | M9: 14460 | N9: 17785 | O9: 16485 | P9: 15440 | Q9: 15879 | R9: 14924.13 | S9: 19021.92 | T9: 20212.22 | U9: 19507.36 | V9: =SUM(C9:U9) -> 293135.63
B10: Pelotas | C10: 6247 | D10: 5237 | E10: 3918 | F10: 3146 | G10: 9858 | H10: 12248 | I10: 7884 | J10: 12870 | K10: 11740 | L10: 12154 | M10: 14504 | N10: 12055 | O10: 12605 | P10: 11500 | Q10: 13541.72 | R10: 11785.99 | S10: 13550 | T10: 12321.22 | U10: 10159.64 | V10: =SUM(C10:U10) -> 197324.57
B11: Cafetería | C11: 0 | D11: 0 | E11: 0 | F11: 5905 | G11: 6950 | H11: 6010 | I11: 7860 | J11: 10720 | K11: 13740 | L11: 10350 | M11: 12565 | N11: 11405 | O11: 9780 | P11: 10875 | Q11: 12011.78 | R11: 8140 | S11: 11242 | T11: 7516.98 | U11: 6024.64 | V11: =SUM(C11:U11) -> 151095.4
B12: Botana | C12: 2585 | D12: 2875 | E12: 2750 | F12: 2845 | G12: 3160 | H12: 3350 | I12: 3675 | J12: 4775 | K12: 7865 | L12: 7495 | M12: 6535 | N12: 9520 | O12: 7945 | P12: 6595 | Q12: 8200 | R12: 6583.16 | S12: 6571.77 | T12: 5980.04 | U12: 4197.43 | V12: =SUM(C12:U12) -> 103502.4
B13: Grips y Palas | C13: 2525 | D13: 4385 | E13: 2180 | F13: 3715 | G13: 3915 | H13: 4120 | I13: 2830 | J13: 2530 | K13: 5080 | L13: 4385 | M13: 2215 | N13: 6740 | O13: 2760 | P13: 3105 | Q13: 3450 | R13: 2150.71 | S13: 2305 | T13: 3065 | U13: 1965 | V13: =SUM(C13:U13) -> 63420.71
B14: Sacos | C14: 0 | D14: 0 | E14: 0 | F14: 0 | G14: 0 | H14: 0 | I14: 0 | J14: 0 | K14: 0 | L14: 0 | M14: 0 | N14: 0 | O14: 0 | P14: 0 | Q14: 700 | R14: 2100 | S14: 0 | T14: 350 | U14: 0 | V14: =SUM(C14:U14) -> 3150
B15: Total ingresos operativos | C15: =SUM(C7:C14) -> 121118.85 | D15: =SUM(D7:D14) -> 122328 | E15: =SUM(E7:E14) -> 132050 | F15: =SUM(F7:F14) -> 152941 | G15: =SUM(G7:G14) -> 175195 | H15: =SUM(H7:H14) -> 192060 | I15: =SUM(I7:I14) -> 165573 | J15: =SUM(J7:J14) -> 193376 | ... U15: =SUM(U7:U14) -> 207796.07 | V15: =SUM(C15:U15) -> 3568682.6
B17: EGRESOS OPERATIVOS
B18: Abogado | C18: 0 | D18: 0 | E18: 0 | F18: 0 | G18: 0 | H18: 0 | I18: 0 | J18: 0 | K18: 0 | L18: 0 | M18: 0 | N18: 0 | O18: 0 | P18: 0 | Q18: 65741.64 | R18: 9110 | S18: 0 | T18: 0 | U18: 0 | V18: =SUM(C18:U18) -> 74851.64
B19: Bono Empleados | C19: 0 | D19: 0 | E19: 0 | F19: 0 | G19: 0 | H19: 0 | I19: 0 | J19: 0 | K19: 0 | L19: 0 | M19: 0 | N19: 0 | O19: 0 | P19: 0 | Q19: 1120 | R19: 2720 | S19: 805 | T19: 745 | U19: 500 | V19: =SUM(C19:U19) -> 5890
B20: Cambio Vidrios | C20: 0 | D20: 18800 | E20: 0 | F20: 0 | G20: 0 | H20: 19080 | I20: 31080 | J20: 0 | K20: 0 | L20: 0 | M20: 0 | N20: 0 | O20: 0 | P20: 0 | Q20: 0 | R20: 0 | S20: 0 | T20: 0 | U20: 0 | V20: =SUM(C20:U20) -> 68960
B21: Contador | C21: 0 | D21: 0 | E21: 0 | F21: 0 | G21: 0 | H21: 0 | I21: 0 | J21: 5220 | K21: 5220 | L21: 5220 | M21: 5220 | N21: 5220 | O21: 5220 | P21: 5220 | Q21: 5220 | R21: 0 | S21: 0 | T21: 7100 | U21: 6960 | V21: =SUM(C21:U21) -> 55820
B22: Costo Limpieza Vidrios | C22: 0 | D22: 2160 | E22: 2340 | F22: 2160 | G22: 2340 | H22: 2340 | I22: 2340 | J22: 2340 | K22: 2340 | L22: 2340 | M22: 2340 | N22: 2340 | O22: 2340 | P22: 2340 | Q22: 1799.1 | R22: 0 | S22: 0 | T22: 0 | U22: 0 | V22: =SUM(C22:U22) -> 31859.1
B23: Costos Inventario | C23: 11305.26 | D23: 10793.43 | E23: 9633 | F23: 19758 | G23: 19792 | H23: 19784 | I23: 17203 | J23: 21260 | K23: 25615 | L23: 21971 | M23: 22536.42 | N23: 24617 | O23: 23816 | P23: 22449 | Q23: 19619 | R23: 20739 | S23: 9921 | T23: 23177 | U23: 22888 | V23: =SUM(C23:U23) -> 366877.11
B24: Empleados | C24: 17000 | D24: 17000 | E24: 17000 | F24: 27000 | G24: 28900 | H24: 27000 | I24: 29500 | J24: 18500 | K24: 23000 | L24: 39000 | M24: 36050 | N24: 24050 | O24: 24200 | P24: 30398 | Q24: 20800 | R24: 20720 | S24: 24060 | T24: 30610 | U24: 21750 | V24: =SUM(C24:U24) -> 476538
B25: Gastos Generales | C25: 6543 | D25: 6689 | E25: 10604 | F25: 28190 | G25: 21448 | H25: 17261 | I25: 19838 | J25: 14760 | K25: 12717 | L25: 7124 | M25: 6685 | N25: 23659 | O25: 21083 | P25: 15306 | Q25: 0 | R25: 0 | S25: 0 | T25: 0 | U25: 0 | V25: =SUM(C25:U25) -> 211907
B26: Insumos Cafetería | C26: 0 | D26: 0 | E26: 0 | F26: 0 | G26: 0 | H26: 0 | I26: 0 | J26: 0 | K26: 0 | L26: 0 | M26: 0 | N26: 0 | O26: 0 | P26: 0 | Q26: 6639.8 | R26: 8063 | S26: 8241 | T26: 1751 | U26: 3113 | V26: =SUM(C26:U26) -> 27807.8
B27: Limpieza general | C27: 2800 | D27: 2700 | E27: 2800 | F27: 2800 | G27: 2800 | H27: 2800 | I27: 3150 | J27: 2800 | K27: 3500 | L27: 2800 | M27: 3150 | N27: 3500 | O27: 2800 | P27: 3150 | Q27: 2450 | R27: 2220 | S27: 2660 | T27: 3040 | U27: 2340 | V27: =SUM(C27:U27) -> 54260
B28: Mantenimiento | C28: 16753 | D28: 4780 | E28: 11540 | F28: 5731 | G28: 0 | H28: 539 | I28: 1400 | J28: 9000 | K28: 1250 | L28: 1960 | M28: 2395 | N28: 9140 | O28: 26762 | P28: 4251 | Q28: 14771 | R28: 862 | S28: 5000 | T28: 2160 | U28: 5221 | V28: =SUM(C28:U28) -> 123515
B29: Mejoras | C29: 0 | D29: 0 | E29: 0 | F29: 0 | G29: 0 | H29: 0 | I29: 0 | J29: 0 | K29: 0 | L29: 0 | M29: 0 | N29: 0 | O29: 0 | P29: 0 | Q29: 423.7 | R29: 6012 | S29: 5187 | T29: 3091 | U29: 0 | V29: =SUM(C29:U29) -> 14713.7
... B34: Sueldo Gerente | C34: 0 | D34: 0 | E34: 0 | F34: 0 | G34: 0 | H34: 0 | I34: 0 | J34: 0 | K34: 0 | L34: 0 | M34: 0 | N34: 0 | O34: 0 | P34: 0 | Q34: 0 | R34: 0 | S34: 17408 | T34: 13452 | U34: 15870 | V34: =SUM(C34:U34) -> 46730
B35: Total egresos operativos | C35: =SUM(C18:C34) -> 69866.26 | D35: =SUM(D18:D34) -> 70283.43 | E35: =SUM(E18:E34) -> 61744 | F35: =SUM(F18:F34) -> 97791 | G35: =SUM(G18:G34) -> 85287 | H35: =SUM(H18:H34) -> 108268 | I35: =SUM(I18:I34) -> 117575 | J35: =SUM(J18:J34) -> 104841.5 | ... U35: =SUM(U18:U34) -> 115858 | V35: =SUM(C35:U35) -> 2029654.1
B36: EBITDA operativo ajustado | C36: =C15-C35 -> 51252.59 | D36: =D15-D35 -> 52044.57 | E36: =E15-E35 -> 70306 | F36: =F15-F35 -> 55150 | G36: =G15-G35 -> 89908 | H36: =H15-H35 -> 83792 | I36: =I15-I35 -> 47998 | J36: =J15-J35 -> 88534.5 | ... U36: =U15-U35 -> 91938.07 | V36: =SUM(C36:U36) -> 1539028.5
B38: PARTIDAS NO OPERATIVAS (excluidas del EBITDA, sí afectan el efectivo)
B39: Sueldo Director General (propietario saliente) | C39: 0 | D39: 0 | E39: 0 | F39: 0 | G39: 0 | H39: 0 | I39: 0 | J39: 0 | K39: 0 | L39: 0 | M39: 0 | N39: 0 | O39: 0 | P39: 0 | Q39: 44332.45 | R39: 40000 | S39: 40000 | T39: 40000 | U39: 40000 | V39: =SUM(C39:U39) -> 204332.45
B40: Renta personal | C40: 17500 | D40: 18849 | E40: 17500 | F40: 17500 | G40: 17500 | H40: 24397 | I40: 28897 | J40: 18250 | K40: 18250 | L40: 47714 | M40: 60216 | N40: 18250 | O40: 30948 | P40: 18250 | Q40: 0 | R40: 0 | S40: 0 | T40: 0 | U40: 0 | V40: =SUM(C40:U40) -> 354021
B41: Alimentación personal | C41: 6167 | D41: 7952 | E41: 9909 | F41: 4752 | G41: 9157 | H41: 7328 | I41: 5175 | J41: 5441 | K41: 10467 | L41: 14829 | M41: 15665 | N41: 12833 | O41: 16404 | P41: 15165 | Q41: 0 | R41: 0 | S41: 0 | T41: 0 | U41: 0 | V41: =SUM(C41:U41) -> 141244
B42: Transporte TAG / gasolina personal | C42: 2482 | D42: 3964 | E42: 700 | F42: 1500 | G42: 2158 | H42: 1500 | I42: 1619 | J42: 4428 | K42: 35552 | L42: 7225 | M42: 5995 | N42: 10300 | O42: 3378 | P42: 15165 | Q42: 0 | R42: 0 | S42: 0 | T42: 0 | U42: 0 | V42: =SUM(C42:U42) -> 95966
B43: Gastos personales pagados por el club | C43: =SUM(C40:C42) -> 26149 | D43: =SUM(D40:D42) -> 30765 | E43: =SUM(E40:E42) -> 28109 | F43: =SUM(F40:F42) -> 23752 | G43: =SUM(G40:G42) -> 28815 | H43: =SUM(H40:H42) -> 33225 | I43: =SUM(I40:I42) -> 35691 | J43: =SUM(J40:J42) -> 28119 | ... U43: =SUM(U40:U42) -> 0 | V43: =SUM(C43:U43) -> 591231
B44: Retiros de utilidades de socios (bitácora) | C44: 0 | D44: 0 | E44: 0 | F44: 0 | G44: 0 | H44: 0 | I44: 0 | J44: 0 | K44: 64000 | L44: 0 | M44: 100000 | N44: 0 | O44: 0 | P44: 38000 | Q44: 0 | R44: 0 | S44: 26000 | T44: 0 | U44: 0 | V44: =SUM(C44:U44) -> 228000
B45: Fondo Apapacho — ingreso (pass-through) | C45: 0 | D45: 0 | E45: 1110 | F45: 0 | G45: 300 | H45: 0 | I45: 0 | J45: 0 | K45: 0 | L45: 50 | M45: 0 | N45: 750 | O45: 1050 | P45: 700 | Q45: 950 | R45: 400 | S45: 550 | T45: 600 | U45: 900 | V45: =SUM(C45:U45) -> 7360
B46: Fondo Apapacho — egreso (pass-through) | C46: 0 | D46: 0 | E46: 1110 | F46: 0 | G46: 300 | H46: 0 | I46: 0 | J46: 0 | K46: 0 | L46: 50 | M46: 0 | N46: 750 | O46: 1050 | P46: 700 | Q46: 950 | R46: 400 | S46: 550 | T46: 600 | U46: 900 | V46: =SUM(C46:U46) -> 7360
B48: FLUJO SEGÚN REGISTROS
B49: Flujo neto del mes según registros | C49: =C36-C39-C43-C44+C45-C46 -> 25103.59 | D49: =D36-D39-D43-D44+D45-D46 -> 21279.57 | E49: =E36-E39-E43-E44+E45-E46 -> 42197 | F49: =F36-F39-F43-F44+F45-F46 -> 31398 | G49: =G36-G39-G43-G44+G45-G46 -> 61093 | H49: =H36-H39-H43-H44+H45-H46 -> 50567 | I49: =I36-I39-I43-I44+I45-I46 -> 12307 | J49: =J36-J39-J43-J44+J45-J46 -> 60415.5 | ... U49: =U36-U39-U43-U44+U45-U46 -> 51938.07 | V49: =SUM(C49:U49) -> 515465.03
...
